Workbook
Name impfibra: implantacao!$A:$V
Name servicossistemas: servicos!$D$8:$D$163
Name Print_Area: 'orcamento-2026'!$A$1:$R$78
Name municipios: regiao!$A$6:$A$150
Name indiceclientesimp: implantacao!$B:$B
Name mesorregioes: regiao!$L$168:$L$173

Sheet orcamento-2026
B1: EMPRESA DE TECNOLOGIA DA INFORMAÇÃO E COMUNICAÇÃO DO ESTADO DO PARÁ
A3: Emissão: | B3: =TODAY() -> 46232 | H3: Orçamento nº | K3: 057/2026
A4: DADOS DO CLIENTE | P4: OCULTAR | X4: Contatos
A5: Cliente: | B5: =VLOOKUP(N5,clientes!A:B,2,0) -> Tribunal de Contas do Estado | N5: TCE | X5: =IFERROR(__xludf.DUMMYFUNCTION("IFERROR(FILTER(contatos!D:D, contatos!$C:$C = $N$5), ""..."")"),"Thyago Souza de Andrade") -> Thyago Souza de Andrade
A6: CNPJ: | B6: =VLOOKUP(N5,clientes!A:H,4,0) | X6: =IFERROR(__xludf.DUMMYFUNCTION("""COMPUTED_VALUE"""),"Mônica Regina Câmara") -> Mônica Regina Câmara
A7: Endereço: | B7: =CONCATENATE(VLOOKUP($N$5,clientes!A:M,8,0)," , ",VLOOKUP($N$5,clientes!A:M,9,0)," , ",VLOOKUP($N$5,clientes!A:L,11,0)," , ",VLOOKUP($N$5,clientes!A:M,12,0)) -> Tv. Quintino Bocaiúva, 1585 , Nazaré , Belém , PA
A8: Nome: | B8: Thyago Souza de Andrade
A9: Cargo: | B9: {=IFERROR(XLOOKUP($B$8, contatos!$D:$D, contatos!E:E), " ")}
A10: Setor: | B10: {=IFERROR(XLOOKUP($B$8, contatos!$D:$D, contatos!F:F), " ")} -> Coordenadoria de Infraestrutura e Segurança - Secretaria de Tecnologia da Informação
A11: E-mail: | B11: {=IFERROR(TEXTJOIN(" ", TRUE, XLOOKUP($B$8, contatos!$D:$D, contatos!I:I), XLOOKUP($B$8, contatos!$D:$D, contatos!J:J)), " ")} -> thyago.andrade@tcepa.tc.br
A12: Telefone | B12: {=IFERROR(TEXTJOIN(" ", TRUE, XLOOKUP($B$8, contatos!$D:$D, contatos!G:G), XLOOKUP($B$8, contatos!$D:$D, contatos!H:H)), " ")} -> (91) 3210-0530
A14: 5.1 - INSTALAÇÃO | O14: OCULTAR
A15: Item | B15: Município | C15: Região | D15: Nome | E15: Código | F15: Serviço | G15: Tipo | H15: Status | I15: Incluir | J15: Qtd | K15: Grandeza | L15: Custo | M15: Ocultar | N15: Total | O15: Ativação | P15: Configuração | Q15: Desp Adm | R15: Com/Sem | S15: Reaparelhamento | T15: Impostos | U15: Coluna 1 | V15: Coluna 2 | W15: Coluna 3 | X15: Coluna 4
A16: =ROW()-ROW(tabelaimplantacao_3[[#HEADERS],[Item]]) -> 1 | B16: PARAGOMINAS | C16: =ifna(VLOOKUP(B16,regiao[[#ALL],[MUNICÍPIO]:[REGIAO_INTEGRACAO]],5,0),"") -> SUDESTE | D16: SINE | E16: {=XLOOKUP(F16&G16,servicos!F:F,servicos!C:C)} -> 5300 | F16: Implantação de infraestrutura de | G16: FIBRA | H16: Previsto | I16: FALSE | J16: 1 | K16: {=XLOOKUP(F16&G16,servicos!$F:$F,servicos!I:I,"Não encontrado",0,1)} -> Configuração, Cabeamento, Equipamento | L16: 0 | N16: =IF(O15<>0,tabelaimplantacao_3[Custo]+tabelaimplantacao_3[Ativação]+tabelaimplantacao_3[Configuração]+tabelaimplantacao_3[Desp Adm]+tabelaimplantacao_3[Reaparelhamento]+tabelaimplantacao_3[Impostos],0) -> 885.41606 | O16: =IF(tabelaimplantacao_3[Tipo]="Fibra",pconfig!$G$7,pconfig!$G$7) -> 285.71 | P16: =IF(tabelaimplantacao_3[Tipo]="Radio",pconfig!$G$9,pconfig!$G$8) -> 316.45 | Q16: =(tabelaimplantacao_3[Custo]+tabelaimplantacao_3[Ativação]+tabelaimplantacao_3[Configuração])*pconfig!$G$2 -> 60.216 | R16: TRUE | S16: =IF(R16<>FALSE,(tabelaimplantacao_3[Custo]+tabelaimplantacao_3[Ativação]+tabelaimplantacao_3[Configuração])*pconfig!$G$3,0) -> 120.432 | T16: =(tabelaimplantacao_3[Custo]+tabelaimplantacao_3[Ativação]+tabelaimplantacao_3[Configuração])*pconfig!$G$4 -> 102.60806
A17: =ROW()-ROW(tabelaimplantacao_3[[#HEADERS],[Item]]) -> 2 | B17: ANANINDEUA | C17: =ifna(VLOOKUP(B17,regiao[[#ALL],[MUNICÍPIO]:[REGIAO_INTEGRACAO]],5,0),"") -> METROPOLITANA | D17: SINE | E17: {=XLOOKUP(F17&G17,servicos!F:F,servicos!C:C)} -> 5300 | F17: Implantação de infraestrutura de | G17: FIBRA | H17: Previsto | I17: FALSE | J17: 1 | K17: {=XLOOKUP(F17&G17,servicos!$F:$F,servicos!I:I,"Não encontrado",0,1)} -> Configuração, Cabeamento, Equipamento | L17: 0 | N17: =IF(O16<>0,tabelaimplantacao_3[Custo]+tabelaimplantacao_3[Ativação]+tabelaimplantacao_3[Configuração]+tabelaimplantacao_3[Desp Adm]+tabelaimplantacao_3[Reaparelhamento]+tabelaimplantacao_3[Impostos],0) -> 885.41606 | O17: =IF(tabelaimplantacao_3[Tipo]="Fibra",pconfig!$G$7,pconfig!$G$7) -> 285.71 | P17: =IF(tabelaimplantacao_3[Tipo]="Radio",pconfig!$G$9,pconfig!$G$8) -> 316.45 | Q17: =(tabelaimplantacao_3[Custo]+tabelaimplantacao_3[Ativação]+tabelaimplantacao_3[Configuração])*pconfig!$G$2 -> 60.216 | R17: TRUE | S17: =IF(R17<>FALSE,(tabelaimplantacao_3[Custo]+tabelaimplantacao_3[Ativação]+tabelaimplantacao_3[Configuração])*pconfig!$G$3,0) -> 120.432 | T17: =(tabelaimplantacao_3[Custo]+tabelaimplantacao_3[Ativação]+tabelaimplantacao_3[Configuração])*pconfig!$G$4 -> 102.60806
A18: TOTAL IMPLANTAÇÃO | N18: =SUMIF(tabelaimplantacao_3[[#ALL],[Incluir]],TRUE,tabelaimplantacao_3[[#ALL],[Total]]) -> 0
A20: 5.2 - SERVIÇOS DE TELECOM - LINK DE DADOS | P20: OCULTAR
A21: Item | B21: Município | C21: Região | D21: Unidade | E21: Código | F21: Serviço | G21: Tipo | H21: Status | I21: Incluir | J21: Qtd | K21: Grandeza | L21: Tabela-ano | M21: Ocultar | N21: Mensal | O21: Total Mensal c/ Reajuste | P21: Unitário | Q21: Preço Manutenção | R21: Total | S21: Mensal 2021 | T21: Mensal 2022 | U21: Mensal 2023 | V21: Mensal 2024 | W21: Mensal 2025 | X21: Mensal 2026 | Y21: 2026-reg
A22: =ROW()-ROW(tabelatelecom_3[[#HEADERS],[Item]]) -> 1 | B22: BELEM | C22: =ifna(VLOOKUP(B22,regiao[[#ALL],[MUNICÍPIO]:[REGIAO_INTEGRACAO]],5,0),"") -> METROPOLITANA | D22: CIIC | E22: {=XLOOKUP(F22&G22,servicos!F:F,servicos!C:C)} -> 5279 | F22: Link de Dados | G22: FIBRA | H22: Ativo | I22: TRUE | J22: 1 | K22: {=XLOOKUP($F22&G22,servicos!$F:$F,servicos!I:I,"Não encontrado",0,1)} -> Mbps | L22: 2025 | N22: =IFS(L22=2021,ROUND(R22,2),L22=2022,ROUND(R22*(1+pconfig!$B$2),2),L22=2023,ROUND(T22*(1+pconfig!$B$3),2),L22=2024,ROUND(U22*(1+pconfig!$B$4),2),L22=2025, ROUND(V22*(1+pconfig!$B$5),2),L22=2026, ROUND(W22*(1+pconfig!$B$6),2),L22="regiaointegracao",Y22*J22) -> 275.91 | O22: =N22*(1+'historico-reajuste'!$C$2)*(1+'historico-reajuste'!$C$3) -> 275.91 | P22: {=XLOOKUP(B22&G22,linkdados!E:E,linkdados!L:L)*J22} -> 23.980363 | Q22: {=XLOOKUP(B22&G22,linkdados!E:E,linkdados!N:N,"")} -> 178.8142 | R22: =IFERROR(__xludf.DUMMYFUNCTION("IF(F22=""Link de Dados"", IFS(J22<=pconfig!$B$12,P22*pconfig!$C$12,J22<=pconfig!$B$13,P22*pconfig!$C$13,J22<=pconfig!$B$14,P22*pconfig!$C$14,J22<=pconfig!$B$15,P22*pconfig!$C$15,J22<=pconfig!$B$16,P22*pconfig!$C$16,J22<=pconfig!$B$17,P22*pconfig!$C$17,J22"&"<=pconfig!$B$18,P22*pconfig!$C$18,J22<=pconfig!$B$19,P22*pconfig!$C$19,J22<=pconfig!$B$20,P22*pconfig!$C$20,J22<=pconfig!$B$21,P22*pconfig!$C$21)+Q22,IF(H22=""Mensal"",FILTER(servicos!O:O,servicos!F:F=F22&G22)*J22,P22))"),202.79456193353474) -> 202.79456 | S22: =IF(F22="Link de Dados",R22,0) -> 202.79456 | T22: =IF(F22="Link de Dados",S22*(1+pconfig!$B$2),S22) -> 238.87171 | U22: =IF(F22="Link de Dados",T22*(1+pconfig!$B$3),T22) -> 254.92389 | V22: =U22*(1+pconfig!$B$4) -> 258.97718 | W22: =V22*(1+pconfig!$B$5) -> 275.91429 | X22: =W22*(1+pconfig!$B$6) -> 284.96428 | Y22: {=XLOOKUP(B22,regiao!A:A,regiao!H:H,0,1)} -> 69.86
A23: =ROW()-ROW(tabelatelecom_3[[#HEADERS],[Item]]) -> 2 | B23: SANTAREM | C23: =ifna(VLOOKUP(B23,regiao[[#ALL],[MUNICÍPIO]:[REGIAO_INTEGRACAO]],5,0),"") -> BAIXO AMAZONAS | D23: ABRIGO LAR DA PROVIDENCIA | E23: {=XLOOKUP(F23&G23,servicos!F:F,servicos!C:C)} -> 5279 | F23: Link de Dados | G23: FIBRA | H23: Ativo | I23: TRUE | J23: 1 | K23: {=XLOOKUP($F23&G23,servicos!$F:$F,servicos!I:I,"Não encontrado",0,1)} -> Mbps | L23: 2022 | N23: =IFS(L23=2021,ROUND(R23,2),L23=2022,ROUND(R23*(1+pconfig!$B$2),2),L23=2023,ROUND(T23*(1+pconfig!$B$3),2),L23=2024,ROUND(U23*(1+pconfig!$B$4),2),L23=2025, ROUND(V23*(1+pconfig!$B$5),2),L23=2026, ROUND(W23*(1+pconfig!$B$6),2),L23="regiaointegracao",Y23*J23) -> 331.28 | O23: =N23*(1+'historico-reajuste'!$C$2)*(1+'historico-reajuste'!$C$3) -> 331.28 | P23: {=XLOOKUP(B23&G23,linkdados!E:E,linkdados!L:L)*J23} -> 29.550604 | Q23: {=XLOOKUP(B23&G23,linkdados!E:E,linkdados!N:N,"")} -> 251.6994 | R23: =IFERROR(__xludf.DUMMYFUNCTION("IF(F23=""Link de Dados"", IFS(J23<=pconfig!$B$12,P23*pconfig!$C$12,J23<=pconfig!$B$13,P23*pconfig!$C$13,J23<=pconfig!$B$14,P23*pconfig!$C$14,J23<=pconfig!$B$15,P23*pconfig!$C$15,J23<=pconfig!$B$16,P23*pconfig!$C$16,J23<=pconfig!$B$17,P23*pconfig!$C$17,J23"&"<=pconfig!$B$18,P23*pconfig!$C$18,J23<=pconfig!$B$19,P23*pconfig!$C$19,J23<=pconfig!$B$20,P23*pconfig!$C$20,J23<=pconfig!$B$21,P23*pconfig!$C$21)+Q23,IF(H23=""Mensal"",FILTER(servicos!O:O,servicos!F:F=F23&G23)*J23,P23))"),281.25000000000006) -> 281.25 | S23: =IF(F23="Link de Dados",R23,0) -> 281.25 | T23: =IF(F23="Link de Dados",S23*(1+pconfig!$B$2),S23) -> 331.28438 | U23: =IF(F23="Link de Dados",T23*(1+pconfig!$B$3),T23) -> 353.54669 | V23: =U23*(1+pconfig!$B$4) -> 359.16808 | W23: =V23*(1+pconfig!$B$5) -> 382.65767 | X23: =W23*(1+pconfig!$B$6) -> 395.20884 | Y23: {=XLOOKUP(B23,regiao!A:A,regiao!H:H,0,1)} -> 72.86
A24: =ROW()-ROW(tabelatelecom_3[[#HEADERS],[Item]]) -> 3 | B24: SANTAREM | C24: =ifna(VLOOKUP(B24,regiao[[#ALL],[MUNICÍPIO]:[REGIAO_INTEGRACAO]],5,0),"") -> BAIXO AMAZONAS | D24: ABRIGO SOCORRO GABRIEL | E24: {=XLOOKUP(F24&G24,servicos!F:F,servicos!C:C)} -> 5279 | F24: Link de Dados | G24: FIBRA | H24: Ativo | I24: TRUE | J24: 1 | K24: {=XLOOKUP($F24&G24,servicos!$F:$F,servicos!I:I,"Não encontrado",0,1)} -> Mbps | L24: 2022 | N24: =IFS(L24=2021,ROUND(R24,2),L24=2022,ROUND(R24*(1+pconfig!$B$2),2),L24=2023,ROUND(T24*(1+pconfig!$B$3),2),L24=2024,ROUND(U24*(1+pconfig!$B$4),2),L24=2025, ROUND(V24*(1+pconfig!$B$5),2),L24=2026, ROUND(W24*(1+pconfig!$B$6),2),L24="regiaointegracao",Y24*J24) -> 331.28 | O24: =N24*(1+'historico-reajuste'!$C$2)*(1+'historico-reajuste'!$C$3) -> 331.28 | P24: {=XLOOKUP(B24&G24,linkdados!E:E,linkdados!L:L)*J24} -> 29.550604 | Q24: {=XLOOKUP(B24&G24,linkdados!E:E,linkdados!N:N,"")} -> 251.6994 | R24: =IFERROR(__xludf.DUMMYFUNCTION("IF(F24=""Link de Dados"", IFS(J24<=pconfig!$B$12,P24*pconfig!$C$12,J24<=pconfig!$B$13,P24*pconfig!$C$13,J24<=pconfig!$B$14,P24*pconfig!$C$14,J24<=pconfig!$B$15,P24*pconfig!$C$15,J24<=pconfig!$B$16,P24*pconfig!$C$16,J24<=pconfig!$B$17,P24*pconfig!$C$17,J24"&"<=pconfig!$B$18,P24*pconfig!$C$18,J24<=pconfig!$B$19,P24*pconfig!$C$19,J24<=pconfig!$B$20,P24*pconfig!$C$20,J24<=pconfig!$B$21,P24*pconfig!$C$21)+Q24,IF(H24=""Mensal"",FILTER(servicos!O:O,servicos!F:F=F24&G24)*J24,P24))"),281.25000000000006) -> 281.25 | S24: =IF(F24="Link de Dados",R24,0) -> 281.25 | T24: =IF(F24="Link de Dados",S24*(1+pconfig!$B$2),S24) -> 331.28438 | U24: =IF(F24="Link de Dados",T24*(1+pconfig!$B$3),T24) -> 353.54669 | V24: =U24*(1+pconfig!$B$4) -> 359.16808 | W24: =V24*(1+pconfig!$B$5) -> 382.65767 | X24: =W24*(1+pconfig!$B$6) -> 395.20884 | Y24: {=XLOOKUP(B24,regiao!A:A,regiao!H:H,0,1)} -> 72.86
A25: =ROW()-ROW(tabelatelecom_3[[#HEADERS],[Item]]) -> 4 | B25: BELEM | C25: =ifna(VLOOKUP(B25,regiao[[#ALL],[MUNICÍPIO]:[REGIAO_INTEGRACAO]],5,0),"") -> METROPOLITANA | D25: PADRE EUTÍQUIO | E25: {=XLOOKUP(F25&G25,servicos!F:F,servicos!C:C)} -> 5279 | F25: Link de Dados | G25: FIBRA | H25: Ativo | I25: TRUE | J25: 1 | K25: {=XLOOKUP($F25&G25,servicos!$F:$F,servicos!I:I,"Não encontrado",0,1)} -> Mbps | L25: 2022 | N25: =IFS(L25=2021,ROUND(R25,2),L25=2022,ROUND(R25*(1+pconfig!$B$2),2),L25=2023,ROUND(T25*(1+pconfig!$B$3),2),L25=2024,ROUND(U25*(1+pconfig!$B$4),2),L25=2025, ROUND(V25*(1+pconfig!$B$5),2),L25=2026, ROUND(W25*(1+pconfig!$B$6),2),L25="regiaointegracao",Y25*J25) -> 238.87 | O25: =N25*(1+'historico-reajuste'!$C$2)*(1+'historico-reajuste'!$C$3) -> 238.87 | P25: {=XLOOKUP(B25&G25,linkdados!E:E,linkdados!L:L)*J25} -> 23.980363 | Q25: {=XLOOKUP(B25&G25,linkdados!E:E,linkdados!N:N,"")} -> 178.8142 | R25: =IFERROR(__xludf.DUMMYFUNCTION("IF(F25=""Link de Dados"", IFS(J25<=pconfig!$B$12,P25*pconfig!$C$12,J25<=pconfig!$B$13,P25*pconfig!$C$13,J25<=pconfig!$B$14,P25*pconfig!$C$14,J25<=pconfig!$B$15,P25*pconfig!$C$15,J25<=pconfig!$B$16,P25*pconfig!$C$16,J25<=pconfig!$B$17,P25*pconfig!$C$17,J25"&"<=pconfig!$B$18,P25*pconfig!$C$18,J25<=pconfig!$B$19,P25*pconfig!$C$19,J25<=pconfig!$B$20,P25*pconfig!$C$20,J25<=pconfig!$B$21,P25*pconfig!$C$21)+Q25,IF(H25=""Mensal"",FILTER(servicos!O:O,servicos!F:F=F25&G25)*J25,P25))"),202.79456193353474) -> 202.79456 | S25: =IF(F25="Link de Dados",R25,0) -> 202.79456 | T25: =IF(F25="Link de Dados",S25*(1+pconfig!$B$2),S25) -> 238.87171 | U25: =IF(F25="Link de Dados",T25*(1+pconfig!$B$3),T25) -> 254.92389 | V25: =U25*(1+pconfig!$B$4) -> 258.97718 | W25: =V25*(1+pconfig!$B$5) -> 275.91429 | X25: =W25*(1+pconfig!$B$6) -> 284.96428 | Y25: {=XLOOKUP(B25,regiao!A:A,regiao!H:H,0,1)} -> 69.86
A26: =ROW()-ROW(tabelatelecom_3[[#HEADERS],[Item]]) -> 5 | B26: BELEM | C26: =ifna(VLOOKUP(B26,regiao[[#ALL],[MUNICÍPIO]:[REGIAO_INTEGRACAO]],5,0),"") -> METROPOLITANA | D26: SEDE | E26: {=XLOOKUP(F26&G26,servicos!F:F,servicos!C:C)} -> 5279 | F26: Link de Dados | G26: FIBRA | H26: Ativo | I26: TRUE | J26: 1 | K26: {=XLOOKUP($F26&G26,servicos!$F:$F,servicos!I:I,"Não encontrado",0,1)} -> Mbps | L26: 2022 | N26: =IFS(L26=2021,ROUND(R26,2),L26=2022,ROUND(R26*(1+pconfig!$B$2),2),L26=2023,ROUND(T26*(1+pconfig!$B$3),2),L26=2024,ROUND(U26*(1+pconfig!$B$4),2),L26=2025, ROUND(V26*(1+pconfig!$B$5),2),L26=2026, ROUND(W26*(1+pconfig!$B$6),2),L26="regiaointegracao",Y26*J26) -> 238.87 | O26: =N26*(1+'historico-reajuste'!$C$2)*(1+'historico-reajuste'!$C$3) -> 238.87 | P26: {=XLOOKUP(B26&G26,linkdados!E:E,linkdados!L:L)*J26} -> 23.980363 | Q26: {=XLOOKUP(B26&G26,linkdados!E:E,linkdados!N:N,"")} -> 178.8142 | R26: =IFERROR(__xludf.DUMMYFUNCTION("IF(F26=""Link de Dados"", IFS(J26<=pconfig!$B$12,P26*pconfig!$C$12,J26<=pconfig!$B$13,P26*pconfig!$C$13,J26<=pconfig!$B$14,P26*pconfig!$C$14,J26<=pconfig!$B$15,P26*pconfig!$C$15,J26<=pconfig!$B$16,P26*pconfig!$C$16,J26<=pconfig!$B$17,P26*pconfig!$C$17,J26"&"<=pconfig!$B$18,P26*pconfig!$C$18,J26<=pconfig!$B$19,P26*pconfig!$C$19,J26<=pconfig!$B$20,P26*pconfig!$C$20,J26<=pconfig!$B$21,P26*pconfig!$C$21)+Q26,IF(H26=""Mensal"",FILTER(servicos!O:O,servicos!F:F=F26&G26)*J26,P26))"),202.79456193353474) -> 202.79456 | S26: =IF(F26="Link de Dados",R26,0) -> 202.79456 | T26: =IF(F26="Link de Dados",S26*(1+pconfig!$B$2),S26) -> 238.87171 | U26: =IF(F26="Link de Dados",T26*(1+pconfig!$B$3),T26) -> 254.92389 | V26: =U26*(1+pconfig!$B$4) -> 258.97718 | W26: =V26*(1+pconfig!$B$5) -> 275.91429 | X26: =W26*(1+pconfig!$B$6) -> 284.96428 | Y26: {=XLOOKUP(B26,regiao!A:A,regiao!H:H,0,1)} -> 69.86
A27: =ROW()-ROW(tabelatelecom_3[[#HEADERS],[Item]]) -> 6 | B27: ANANINDEUA | C27: =ifna(VLOOKUP(B27,regiao[[#ALL],[MUNICÍPIO]:[REGIAO_INTEGRACAO]],5,0),"") -> METROPOLITANA | D27: SINE | E27: {=XLOOKUP(F27&G27,servicos!F:F,servicos!C:C)} -> 5279 | F27: Link de Dados | G27: FIBRA | H27: Ativo | I27: TRUE | J27: 1 | K27: {=XLOOKUP($F27&G27,servicos!$F:$F,servicos!I:I,"Não encontrado",0,1)} -> Mbps | L27: 2022 | N27: =IFS(L27=2021,ROUND(R27,2),L27=2022,ROUND(R27*(1+pconfig!$B$2),2),L27=2023,ROUND(T27*(1+pconfig!$B$3),2),L27=2024,ROUND(U27*(1+pconfig!$B$4),2),L27=2025, ROUND(V27*(1+pconfig!$B$5),2),L27=2026, ROUND(W27*(1+pconfig!$B$6),2),L27="regiaointegracao",Y27*J27) -> 241.7 | O27: =N27*(1+'historico-reajuste'!$C$2)*(1+'historico-reajuste'!$C$3) -> 241.7 | P27: {=XLOOKUP(B27&G27,linkdados!E:E,linkdados!L:L)*J27} -> 26.378399 | Q27: {=XLOOKUP(B27&G27,linkdados!E:E,linkdados!N:N,"")} -> 178.8142 | R27: =IFERROR(__xludf.DUMMYFUNCTION("IF(F27=""Link de Dados"", IFS(J27<=pconfig!$B$12,P27*pconfig!$C$12,J27<=pconfig!$B$13,P27*pconfig!$C$13,J27<=pconfig!$B$14,P27*pconfig!$C$14,J27<=pconfig!$B$15,P27*pconfig!$C$15,J27<=pconfig!$B$16,P27*pconfig!$C$16,J27<=pconfig!$B$17,P27*pconfig!$C$17,J27"&"<=pconfig!$B$18,P27*pconfig!$C$18,J27<=pconfig!$B$19,P27*pconfig!$C$19,J27<=pconfig!$B$20,P27*pconfig!$C$20,J27<=pconfig!$B$21,P27*pconfig!$C$21)+Q27,IF(H27=""Mensal"",FILTER(servicos!O:O,servicos!F:F=F27&G27)*J27,P27))"),205.1925981873112) -> 205.1926 | S27: =IF(F27="Link de Dados",R27,0) -> 205.1926 | T27: =IF(F27="Link de Dados",S27*(1+pconfig!$B$2),S27) -> 241.69636 | U27: =IF(F27="Link de Dados",T27*(1+pconfig!$B$3),T27) -> 257.93836 | V27: =U27*(1+pconfig!$B$4) -> 262.03958 | W27: =V27*(1+pconfig!$B$5) -> 279.17697 | X27: =W27*(1+pconfig!$B$6) -> 288.33397 | Y27: {=XLOOKUP(B27,regiao!A:A,regiao!H:H,0,1)} -> 69.86
A28: =ROW()-ROW(tabelatelecom_3[[#HEADERS],[Item]]) -> 7 | B28: CASTANHAL | C28: =ifna(VLOOKUP(B28,regiao[[#ALL],[MUNICÍPIO]:[REGIAO_INTEGRACAO]],5,0),"") -> METROPOLITANA | D28: CRAS | E28: {=XLOOKUP(F28&G28,servicos!F:F,servicos!C:C)} -> 5279 | F28: Link de Dados | G28: FIBRA | H28: Ativo | I28: TRUE | J28: 1 | K28: {=XLOOKUP($F28&G28,servicos!$F:$F,servicos!I:I,"Não encontrado",0,1)} -> Mbps | L28: 2022 | N28: =IFS(L28=2021,ROUND(R28,2),L28=2022,ROUND(R28*(1+pconfig!$B$2),2),L28=2023,ROUND(T28*(1+pconfig!$B$3),2),L28=2024,ROUND(U28*(1+pconfig!$B$4),2),L28=2025, ROUND(V28*(1+pconfig!$B$5),2),L28=2026, ROUND(W28*(1+pconfig!$B$6),2),L28="regiaointegracao",Y28*J28) -> 188.36 | O28: =N28*(1+'historico-reajuste'!$C$2)*(1+'historico-reajuste'!$C$3) -> 188.36 | P28: {=XLOOKUP(B28&G28,linkdados!E:E,linkdados!L:L)*J28} -> 26.378399 | Q28: {=XLOOKUP(B28&G28,linkdados!E:E,linkdados!N:N,"")} -> 133.53474 | R28: =IFERROR(__xludf.DUMMYFUNCTION("IF(F28=""Link de Dados"", IFS(J28<=pconfig!$B$12,P28*pconfig!$C$12,J28<=pconfig!$B$13,P28*pconfig!$C$13,J28<=pconfig!$B$14,P28*pconfig!$C$14,J28<=pconfig!$B$15,P28*pconfig!$C$15,J28<=pconfig!$B$16,P28*pconfig!$C$16,J28<=pconfig!$B$17,P28*pconfig!$C$17,J28"&"<=pconfig!$B$18,P28*pconfig!$C$18,J28<=pconfig!$B$19,P28*pconfig!$C$19,J28<=pconfig!$B$20,P28*pconfig!$C$20,J28<=pconfig!$B$21,P28*pconfig!$C$21)+Q28,IF(H28=""Mensal"",FILTER(servicos!O:O,servicos!F:F=F28&G28)*J28,P28))"),159.9131419939577) -> 159.91314 | S28: =IF(F28="Link de Dados",R28,0) -> 159.91314 | T28: =IF(F28="Link de Dados",S28*(1+pconfig!$B$2),S28) -> 188.36169 | U28: =IF(F28="Link de Dados",T28*(1+pconfig!$B$3),T28) -> 201.0196 | V28: =U28*(1+pconfig!$B$4) -> 204.21581 | W28: =V28*(1+pconfig!$B$5) -> 217.57152 | X28: =W28*(1+pconfig!$B$6) -> 224.70787 | Y28: {=XLOOKUP(B28,regiao!A:A,regiao!H:H,0,1)} -> 77.04
A29: =ROW()-ROW(tabelatelecom_3[[#HEADERS],[Item]]) -> 8 | B29: PARAGOMINAS | C29: =ifna(VLOOKUP(B29,regiao[[#ALL],[MUNICÍPIO]:[REGIAO_INTEGRACAO]],5,0),"") -> SUDESTE | D29: SINE | E29: {=XLOOKUP(F29&G29,servicos!F:F,servicos!C:C)} -> 5279 | F29: Link de Dados | G29: FIBRA | H29: Ativo | I29: TRUE | J29: 1 | K29: {=XLOOKUP($F29&G29,servicos!$F:$F,servicos!I:I,"Não encontrado",0,1)} -> Mbps | L29: 2022 | N29: =IFS(L29=2021,ROUND(R29,2),L29=2022,ROUND(R29*(1+pconfig!$B$2),2),L29=2023,ROUND(T29*(1+pconfig!$B$3),2),L29=2024,ROUND(U29*(1+pconfig!$B$4),2),L29=2025, ROUND(V29*(1+pconfig!$B$5),2),L29=2026, ROUND(W29*(1+pconfig!$B$6),2),L29="regiaointegracao",Y29*J29) -> 175.8 | O29: =N29*(1+'historico-reajuste'!$C$2)*(1+'historico-reajuste'!$C$3) -> 175.8 | P29: {=XLOOKUP(B29&G29,linkdados!E:E,linkdados!L:L)*J29} -> 29.550604 | Q29: {=XLOOKUP(B29&G29,linkdados!E:E,linkdados!N:N,"")} -> 119.69411 | R29: =IFERROR(__xludf.DUMMYFUNCTION("IF(F29=""Link de Dados"", IFS(J29<=pconfig!$B$12,P29*pconfig!$C$12,J29<=pconfig!$B$13,P29*pconfig!$C$13,J29<=pconfig!$B$14,P29*pconfig!$C$14,J29<=pconfig!$B$15,P29*pconfig!$C$15,J29<=pconfig!$B$16,P29*pconfig!$C$16,J29<=pconfig!$B$17,P29*pconfig!$C$17,J29"&"<=pconfig!$B$18,P29*pconfig!$C$18,J29<=pconfig!$B$19,P29*pconfig!$C$19,J29<=pconfig!$B$20,P29*pconfig!$C$20,J29<=pconfig!$B$21,P29*pconfig!$C$21)+Q29,IF(H29=""Mensal"",FILTER(servicos!O:O,servicos!F:F=F29&G29)*J29,P29))"),149.24471299093656) -> 149.24471 | S29: =IF(F29="Link de Dados",R29,0) -> 149.24471 | T29: =IF(F29="Link de Dados",S29*(1+pconfig!$B$2),S29) -> 175.79535 | U29: =IF(F29="Link de Dados",T29*(1+pconfig!$B$3),T29) -> 187.60879 | V29: =U29*(1+pconfig!$B$4) -> 190.59177 | W29: =V29*(1+pconfig!$B$5) -> 203.05648 | X29: =W29*(1+pconfig!$B$6) -> 209.71673 | Y29: {=XLOOKUP(B29,regiao!A:A,regiao!H:H,0,1)} -> 65.28
A30: =ROW()-ROW(tabelatelecom_3[[#HEADERS],[Item]]) -> 9 | B30: TAILANDIA | C30: =ifna(VLOOKUP(B30,regiao[[#ALL],[MUNICÍPIO]:[REGIAO_INTEGRACAO]],5,0),"") -> NORDESTE | D30: SINE | E30: {=XLOOKUP(F30&G30,servicos!F:F,servicos!C:C)} -> 5262 | F30: Link de Dados | G30: RADIO | H30: Ativo | I30: TRUE | J30: 1 | K30: {=XLOOKUP($F30&G30,servicos!$F:$F,servicos!I:I,"Não encontrado",0,1)} -> Mbps | L30: 2022 | N30: =IFS(L30=2021,ROUND(R30,2),L30=2022,ROUND(R30*(1+pconfig!$B$2),2),L30=2023,ROUND(T30*(1+pconfig!$B$3),2),L30=2024,ROUND(U30*(1+pconfig!$B$4),2),L30=2025, ROUND(V30*(1+pconfig!$B$5),2),L30=2026, ROUND(W30*(1+pconfig!$B$6),2),L30="regiaointegracao",Y30*J30) -> 776.18 | O30: =N30*(1+'historico-reajuste'!$C$2)*(1+'historico-reajuste'!$C$3) -> 776.18 | P30: {=XLOOKUP(B30&G30,linkdados!E:E,linkdados!L:L)*J30} -> 29.550604 | Q30: {=XLOOKUP(B30&G30,linkdados!E:E,linkdados!N:N,"")} -> 629.40584 | R30: =IFERROR(__xludf.DUMMYFUNCTION("IF(F30=""Link de Dados"", IFS(J30<=pconfig!$B$12,P30*pconfig!$C$12,J30<=pconfig!$B$13,P30*pconfig!$C$13,J30<=pconfig!$B$14,P30*pconfig!$C$14,J30<=pconfig!$B$15,P30*pconfig!$C$15,J30<=pconfig!$B$16,P30*pconfig!$C$16,J30<=pconfig!$B$17,P30*pconfig!$C$17,J30"&"<=pconfig!$B$18,P30*pconfig!$C$18,J30<=pconfig!$B$19,P30*pconfig!$C$19,J30<=pconfig!$B$20,P30*pconfig!$C$20,J30<=pconfig!$B$21,P30*pconfig!$C$21)+Q30,IF(H30=""Mensal"",FILTER(servicos!O:O,servicos!F:F=F30&G30)*J30,P30))"),658.9564451158101) -> 658.95645 | S30: =IF(F30="Link de Dados",R30,0) -> 658.95645 | T30: =IF(F30="Link de Dados",S30*(1+pconfig!$B$2),S30) -> 776.1848 | U30: =IF(F30="Link de Dados",T30*(1+pconfig!$B$3),T30) -> 828.34442 | V30: =U30*(1+pconfig!$B$4) -> 841.51509 | W30: =V30*(1+pconfig!$B$5) -> 896.55018 | X30: =W30*(1+pconfig!$B$6) -> 925.95702 | Y30: {=XLOOKUP(B30,regiao!A:A,regiao!H:H,0,1)} -> 87.51
A31: TOTAL MENSAL | N31: =SUMIF(tabelatelecom_3[Incluir],TRUE,tabelatelecom_3[Mensal]) -> 2798.25 | O31: =SUMIF(tabelatelecom_3[Incluir],TRUE,tabelatelecom_3[Total Mensal c/ Reajuste]) -> 2798.25
A32: TOTAL ANUAL | N32: =N31*12 -> 33579 | O32: =O31*12 -> 33579
A35: 5.3 - SERVIÇOS DE INTERNET
A36: Item | B36: Município | C36: Região de Integração | D36: Unidade | E36: Código | F36: Serviço | G36: Tipo | H36: Status | I36: Incluir | J36: Qtd | K36: Grandeza | L36: Unitário | M36: Incluir reajuste | N36: Mensal | O36: Total Mensal c/ Reajuste
A37: =ROW()-ROW(tabelaInternet_4[[#HEADERS],[Item]]) -> 1 | B37: BELEM | C37: =ifna(VLOOKUP(B37,regiao[[#ALL],[MUNICÍPIO]:[REGIAO_INTEGRACAO]],5,0),"") -> METROPOLITANA | D37: SEDE | E37: {=XLOOKUP(F37&G37,servicos!F:F,servicos!C:C)} -> 3174 | F37: Internet | G37: FIBRA | H37: Ativo | I37: TRUE | J37: 300 | K37: {=XLOOKUP($F37&G37,servicos!$F:$F,servicos!I:I,"Não encontrado",0,1)} -> Mbps | L37: Tabela 2026 | M37: FALSE | N37: {=IFS(tabelaInternet_4[Unitário]="Tabela 2026",XLOOKUP(F37&G37,servicos!F:F,servicos!P:P)*tabelaInternet_4[Qtd],tabelaInternet_4[Unitário]="Contrato Cliente",XLOOKUP(F37&G37,servicos!F:F,servicos!N:N)*tabelaInternet_4[Qtd])} -> 6900 | O37: =IF(tabelaInternet_4[Incluir reajuste]=TRUE,tabelaInternet_4[Mensal]*(1+'historico-reajuste'!C3),tabelaInternet_4[Mensal]) -> 6900
A38: TOTAL MENSAL | N38: =SUMIF(tabelaInternet_4[[#DATA],[#TOTALS],[Incluir]],TRUE,tabelaInternet_4[Mensal]) -> 6900 | O38: =SUM(tabelaInternet_4[Total Mensal c/ Reajuste]) -> 6900
A39: TOTAL ANUAL | N39: =N38*12 -> 82800 | O39: =O38*12 -> 82800
A41: SERVIÇOS DE TI
A42: Item | B42: Município | C42: Região | D42: Unidade | E42: Código | F42: Serviço | G42: Grandeza | H42: Status | I42: Incluir | J42: Qtd | K42: Tabela | L42: Unitário | M42: Ocultar | N42: Mensal | O42: Total Mensal c/ Reajuste
A43: =ROW()-ROW(tabelati_3[[#HEADERS],[Item]]) -> 1 | B43: BELEM | C43: =ifna(VLOOKUP(B43,regiao[[#ALL],[MUNICÍPIO]:[REGIAO_INTEGRACAO]],5,0),"") -> METROPOLITANA | D43: Sede | E43: {=XLOOKUP(F43,servicos!D:D,servicos!C:C)} -> 5581 | F43: Business Intelligence Web - B.I. | G43: {=XLOOKUP(F43,servicos!D:D,servicos!I:I)} -> Licença de software | H43: Ativo | I43: TRUE | J43: 1 | K43: Contrato Cliente | L43: {=ifs(K43=2025,XLOOKUP(F43,servicos!D:D,servicos!O:O),K43=2026,XLOOKUP(F43,servicos!D:D,servicos!P:P),K43="Contrato Cliente",XLOOKUP(F43,servicos!D:D,servicos!N:N))} -> 790.9 | N43: =L43*J43 -> 790.9 | O43: =N43*(1+'historico-reajuste'!$C$3) -> 790.9
A44: =ROW()-ROW(tabelati_3[[#HEADERS],[Item]]) -> 2 | B44: BELEM | C44: =ifna(VLOOKUP(B44,regiao[[#ALL],[MUNICÍPIO]:[REGIAO_INTEGRACAO]],5,0),"") -> METROPOLITANA | D44: Sede | E44: {=XLOOKUP(F44,servicos!D:D,servicos!C:C)} -> 3429 | F44: Licença de Uso Sistema Globais (SIMAS/SIAFEM) | G44: {=XLOOKUP(F44,servicos!D:D,servicos!I:I)} -> Licença de software | H44: Ativo | I44: TRUE | J44: 20 | K44: Contrato Cliente | L44: {=ifs(K44=2025,XLOOKUP(F44,servicos!D:D,servicos!O:O),K44=2026,XLOOKUP(F44,servicos!D:D,servicos!P:P),K44="Contrato Cliente",XLOOKUP(F44,servicos!D:D,servicos!N:N))} -> 735.81 | N44: =L44*J44 -> 14716.2 | O44: =N44*(1+'historico-reajuste'!$C$3) -> 14716.2
A45: =ROW()-ROW(tabelati_3[[#HEADERS],[Item]]) -> 3 | B45: BELEM | C45: =ifna(VLOOKUP(B45,regiao[[#ALL],[MUNICÍPIO]:[REGIAO_INTEGRACAO]],5,0),"") -> METROPOLITANA | D45: Sede | E45: {=XLOOKUP(F45,servicos!D:D,servicos!C:C)} -> 3435 | F45: Licença de Uso Sistemas Específicos (ID CIVIL) | G45: {=XLOOKUP(F45,servicos!D:D,servicos!I:I)} -> Licença de software | H45: Ativo | I45: TRUE | J45: 1 | K45: Contrato Cliente | L45: {=ifs(K45=2025,XLOOKUP(F45,servicos!D:D,servicos!O:O),K45=2026,XLOOKUP(F45,servicos!D:D,servicos!P:P),K45="Contrato Cliente",XLOOKUP(F45,servicos!D:D,servicos!N:N))} -> 463.72 | N45: =L45*J45 -> 463.72 | O45: =N45*(1+'historico-reajuste'!$C$3) -> 463.72
A46: =ROW()-ROW(tabelati_3[[#HEADERS],[Item]]) -> 4 | B46: BELEM | C46: =ifna(VLOOKUP(B46,regiao[[#ALL],[MUNICÍPIO]:[REGIAO_INTEGRACAO]],5,0),"") -> METROPOLITANA | D46: Sede | E46: {=XLOOKUP(F46,servicos!D:D,servicos!C:C)} | F46: Licença de uso de sistema (SUAS) | G46: {=XLOOKUP(F46,servicos!D:D,servicos!I:I)} -> Licença de software | H46: Ativo | I46: TRUE | J46: 1 | K46: Contrato Cliente | L46: {=ifs(K46=2025,XLOOKUP(F46,servicos!D:D,servicos!O:O),K46=2026,XLOOKUP(F46,servicos!D:D,servicos!P:P),K46="Contrato Cliente",XLOOKUP(F46,servicos!D:D,servicos!N:N))} -> 2296.58 | N46: =L46*J46 -> 2296.58 | O46: =N46*(1+'historico-reajuste'!$C$3) -> 2296.58
...

Sheet servicos
A1: Área | B1: Subárea | C1: Codigo | D1: Descrição | E1: Tipo | F1: Coluna 2 | G1: Lim inferior | H1: Lim Superior | I1: Grandeza | J1: Preço Pacote | K1: Tipo de faturamento | L1: Pagamento anual 2025 | M1: Pagamento anual 2026 | N1: Unitário Contrato Cliente | O1: Mensal 2025 | P1: Mensal 2026
A2: 1 - Comunicação de Dados | B2: TELECOM | C2: 5300 | D2: Implantação de infraestrutura de | E2: FIBRA | F2: =D2&E2 -> Implantação de infraestrutura deFIBRA | I2: Configuração, Cabeamento, Equipamento | K2: Pagamento único anual | L2: sob consulta | M2: =(if(L2="sob consulta","sob consulta", ROUND(L2*(1+pconfig!$B$6),2))) -> sob consulta | O2: 0 | P2: =(if(O2="sob consulta","sob consulta", ROUND(O2*(1+pconfig!$B$6),2))) -> 0
A3: 1 - Comunicação de Dados | B3: TELECOM | C3: 5291 | D3: Implantação de infraestrutura de | E3: RADIO | F3: =D3&E3 -> Implantação de infraestrutura deRADIO | I3: Configuração, Equipamento, Cabeamento | K3: Pagamento único anual | L3: sob consulta | M3: =(if(L3="sob consulta","sob consulta", ROUND(L3*(1+pconfig!$B$6),2))) -> sob consulta | O3: 0 | P3: =(if(O3="sob consulta","sob consulta", ROUND(O3*(1+pconfig!$B$6),2))) -> 0
A4: 1 - Comunicação de Dados | B4: TELECOM | C4: 5279 | D4: Link de Dados | E4: FIBRA | F4: =D4&E4 -> Link de DadosFIBRA | I4: Mbps | J4: sob consulta | K4: Mensal | L4: sob consulta | M4: =(if(L4="sob consulta","sob consulta", ROUND(L4*(1+pconfig!$B$6),2))) -> sob consulta | O4: 0 | P4: =(if(O4="sob consulta","sob consulta", ROUND(O4*(1+pconfig!$B$6),2))) -> 0
A5: 1 - Comunicação de Dados | B5: TELECOM | C5: 5262 | D5: Link de Dados | E5: RADIO | F5: =D5&E5 -> Link de DadosRADIO | I5: Mbps | J5: sob consulta | K5: Mensal | L5: sob consulta | M5: =(if(L5="sob consulta","sob consulta", ROUND(L5*(1+pconfig!$B$6),2))) -> sob consulta | O5: 0 | P5: =(if(O5="sob consulta","sob consulta", ROUND(O5*(1+pconfig!$B$6),2))) -> 0
A6: 1 - Comunicação de Dados | B6: Internet | C6: 3174 | D6: Internet | E6: FIBRA | F6: =D6&E6 -> InternetFIBRA | I6: Mbps | K6: Mensal | M6: =(if(L6="sob consulta","sob consulta", ROUND(L6*(1+pconfig!$B$6),2))) -> 0 | N6: 65.97 | O6: 23 | P6: 23
A7: 1 - Comunicação de Dados | B7: Internet | C7: 3174 | D7: Internet | E7: RADIO | F7: =D7&E7 -> InternetRADIO | I7: Mbps | K7: Mensal | M7: =(if(L7="sob consulta","sob consulta", ROUND(L7*(1+pconfig!$B$6),2))) -> 0 | N7: 65.97 | O7: 23 | P7: 23
A8: 2 - Data Center | B8: Hospedagem | D8: REGISTRO DE DOMÍNIO | F8: =D8&E8 -> REGISTRO DE DOMÍNIO | I8: Configuração | K8: Pagamento único anual | L8: 66.09 | M8: =(if(L8="sob consulta","sob consulta", ROUND(L8*(1+pconfig!$B$6),2))) -> 68.26 | O8: 0 | P8: =(if(O8="sob consulta","sob consulta", ROUND(O8*(1+pconfig!$B$6),2))) -> 0
A9: 2 - Data Center | B9: Hospedagem | D9: Locação de Espaço em Disco | F9: =D9&E9 -> Locação de Espaço em Disco | I9: GB | K9: Mensal | M9: =(if(L9="sob consulta","sob consulta", ROUND(L9*(1+pconfig!$B$6),2))) -> 0 | O9: 1.03 | P9: =(if(O9="sob consulta","sob consulta", ROUND(O9*(1+pconfig!$B$6),2))) -> 1.06
A10: 2 - Data Center | B10: Hospedagem | D10: Hospedagem de Servidor (colocation) - 1U | E10: 1U | F10: =D10&E10 -> Hospedagem de Servidor (colocation) - 1U1U | I10: U | K10: Mensal | M10: =(if(L10="sob consulta","sob consulta", ROUND(L10*(1+pconfig!$B$6),2))) -> 0 | O10: 712.35 | P10: =(if(O10="sob consulta","sob consulta", ROUND(O10*(1+pconfig!$B$6),2))) -> 735.72
A11: 2 - Data Center | B11: Hospedagem | D11: Hospedagem de Rack de Servidores - 22 U | E11: 22 U | F11: =D11&E11 -> Hospedagem de Rack de Servidores - 22 U22 U | I11: U | K11: Mensal | M11: =(if(L11="sob consulta","sob consulta", ROUND(L11*(1+pconfig!$B$6),2))) -> 0 | O11: 11371.59 | P11: =ROUND(O11*(1+pconfig!$B$6),2) -> 11744.58
A12: 2 - Data Center | B12: Hospedagem | D12: Hospedagem de Rack de Servidores (compartilhado) - 44U | E12: 44 U | F12: =D12&E12 -> Hospedagem de Rack de Servidores (compartilhado) - 44U44 U | I12: U | K12: Mensal | M12: =(if(L12="sob consulta","sob consulta", ROUND(L12*(1+pconfig!$B$6),2))) -> 0 | O12: 22743.2 | P12: =ROUND(O12*(1+pconfig!$B$6),2) -> 23489.18
A13: 2 - Data Center | B13: Hospedagem | D13: Hosped. de Rack de Servidores (exclusivo) - 44 U | E13: 44 U | F13: =D13&E13 -> Hosped. de Rack de Servidores (exclusivo) - 44 U44 U | I13: U | K13: Mensal | M13: =(if(L13="sob consulta","sob consulta", ROUND(L13*(1+pconfig!$B$6),2))) -> 0 | O13: 29566.16 | P13: =ROUND(O13*(1+pconfig!$B$6),2) -> 30535.93
A14: 2 - Data Center | B14: Hospedagem | D14: Hospedagem de Servidor Storage (colocation) | F14: =D14&E14 -> Hospedagem de Servidor Storage (colocation) | I14: Máquina | J14: sob consulta | K14: Mensal | L14: sob consulta | M14: =(if(L14="sob consulta","sob consulta", ROUND(L14*(1+pconfig!$B$6),2))) -> sob consulta | O14: 0 | P14: =ROUND(O14*(1+pconfig!$B$6),2) -> 0
A15: 3 - Data Center | B15: Hospedagem | D15: Hospedagem de Servidor Virtualizado | F15: =D15&E15 -> Hospedagem de Servidor Virtualizado | I15: Máquina | J15: sob consulta | K15: Mensal | L15: sob consulta | M15: =(if(L15="sob consulta","sob consulta", ROUND(L15*(1+pconfig!$B$6),2))) -> sob consulta | O15: 0 | P15: =ROUND(O15*(1+pconfig!$B$6),2) -> 0
A16: 4 - Data Center | B16: Hospedagem | C16: 5003 | D16: Hospedagem de Website (5Gb) | E16: =IFERROR(__xludf.DUMMYFUNCTION("CONCATENATE(REGEXEXTRACT(D16,""[\d]+""),""GB"")"),"5GB") -> 5GB | F16: =D16&E16 -> Hospedagem de Website (5Gb)5GB | G16: 1 | H16: 5 | I16: GB | K16: Mensal | M16: =(if(L16="sob consulta","sob consulta", ROUND(L16*(1+pconfig!$B$6),2))) -> 0 | O16: 33.73 | P16: =ROUND(O16*(1+pconfig!$B$6),2) -> 34.84
A17: 2 - Data Center | B17: Hospedagem | D17: Hospedagem de Website (10Gb) | E17: =IFERROR(__xludf.DUMMYFUNCTION("CONCATENATE(REGEXEXTRACT(D17,""[\d]+""),""GB"")"),"10GB") -> 10GB | F17: =D17&E17 -> Hospedagem de Website (10Gb)10GB | G17: 1 | H17: 10 | I17: GB | K17: Mensal | M17: =(if(L17="sob consulta","sob consulta", ROUND(L17*(1+pconfig!$B$6),2))) -> 0 | O17: 62.37 | P17: =ROUND(O17*(1+pconfig!$B$6),2) -> 64.42
A18: 2 - Data Center | B18: Hospedagem | C18: 5010 | D18: Hospedagem de Website (30Gb) | E18: =IFERROR(__xludf.DUMMYFUNCTION("CONCATENATE(REGEXEXTRACT(D18,""[\d]+""),""GB"")"),"30GB") -> 30GB | F18: =D18&E18 -> Hospedagem de Website (30Gb)30GB | G18: 1 | H18: 30 | I18: GB | K18: Mensal | M18: =(if(L18="sob consulta","sob consulta", ROUND(L18*(1+pconfig!$B$6),2))) -> 0 | N18: 76.13 | O18: 82.9 | P18: =ROUND(O18*(1+pconfig!$B$6),2) -> 85.62
A19: 2 - Data Center | B19: Hospedagem | D19: Hospedagem de Website (50Gb) | E19: =IFERROR(__xludf.DUMMYFUNCTION("CONCATENATE(REGEXEXTRACT(D19,""[\d]+""),""GB"")"),"50GB") -> 50GB | F19: =D19&E19 -> Hospedagem de Website (50Gb)50GB | G19: 1 | H19: 50 | I19: GB | K19: Mensal | M19: =(if(L19="sob consulta","sob consulta", ROUND(L19*(1+pconfig!$B$6),2))) -> 0 | O19: 103.46 | P19: =ROUND(O19*(1+pconfig!$B$6),2) -> 106.85
A20: 2 - Data Center | B20: Hospedagem | C20: 5026 | D20: Hospedagem de Website (100Gb) | E20: =IFERROR(__xludf.DUMMYFUNCTION("CONCATENATE(REGEXEXTRACT(D20,""[\d]+""),""GB"")"),"100GB") -> 100GB | F20: =D20&E20 -> Hospedagem de Website (100Gb)100GB | G20: 1 | H20: 100 | I20: GB | K20: Mensal | M20: =(if(L20="sob consulta","sob consulta", ROUND(L20*(1+pconfig!$B$6),2))) -> 0 | O20: 154.8 | P20: =ROUND(O20*(1+pconfig!$B$6),2) -> 159.88
A21: 2 - Data Center | B21: Hospedagem | C21: 5530 | D21: Conta de Email (1Gb) 1 Cx | E21: =IFERROR(__xludf.DUMMYFUNCTION("CONCATENATE(REGEXEXTRACT(D21,""[\d]+""),""GB"")"),"1GB") -> 1GB | F21: =D21&E21 -> Conta de Email (1Gb) 1 Cx1GB | G21: 1 | H21: 1 | I21: GB | J21: 6.24 | K21: Mensal | M21: =(if(L21="sob consulta","sob consulta", ROUND(L21*(1+pconfig!$B$6),2))) -> 0 | O21: =J21/H21 -> 6.24 | P21: =ROUND(O21*(1+pconfig!$B$6),2) -> 6.44
A22: 2 - Data Center | B22: Hospedagem | C22: 5530 | D22: Conta de Email (1Gb) 25 Cx | E22: =IFERROR(__xludf.DUMMYFUNCTION("CONCATENATE(REGEXEXTRACT(D22,""[\d]+""),""GB"")"),"1GB") -> 1GB | F22: =D22&E22 -> Conta de Email (1Gb) 25 Cx1GB | G22: 1 | H22: 25 | I22: GB | J22: 149.76 | K22: Mensal | M22: =(if(L22="sob consulta","sob consulta", ROUND(L22*(1+pconfig!$B$6),2))) -> 0 | O22: =J22/H22 -> 5.9904 | P22: =ROUND(O22*(1+pconfig!$B$6),2) -> 6.19
A23: 2 - Data Center | B23: Hospedagem | C23: 5530 | D23: Conta de Email (1Gb) 50 Cx | E23: =IFERROR(__xludf.DUMMYFUNCTION("CONCATENATE(REGEXEXTRACT(D23,""[\d]+""),""GB"")"),"1GB") -> 1GB | F23: =D23&E23 -> Conta de Email (1Gb) 50 Cx1GB | G23: 1 | H23: 50 | I23: GB | J23: 293.28 | K23: Mensal | M23: =(if(L23="sob consulta","sob consulta", ROUND(L23*(1+pconfig!$B$6),2))) -> 0 | O23: =J23/H23 -> 5.8656 | P23: =ROUND(O23*(1+pconfig!$B$6),2) -> 6.06
A24: 2 - Data Center | B24: Hospedagem | C24: 5530 | D24: Conta de Email (1Gb) 100 Cx | E24: =IFERROR(__xludf.DUMMYFUNCTION("CONCATENATE(REGEXEXTRACT(D24,""[\d]+""),""GB"")"),"1GB") -> 1GB | F24: =D24&E24 -> Conta de Email (1Gb) 100 Cx1GB | G24: 1 | H24: 100 | I24: GB | J24: 574.08 | K24: Mensal | M24: =(if(L24="sob consulta","sob consulta", ROUND(L24*(1+pconfig!$B$6),2))) -> 0 | O24: =J24/H24 -> 5.7408 | P24: =ROUND(O24*(1+pconfig!$B$6),2) -> 5.93
A25: 2 - Data Center | B25: Hospedagem | C25: 5530 | D25: Conta de Email (1Gb) 500 Cx NOVO | E25: =IFERROR(__xludf.DUMMYFUNCTION("CONCATENATE(REGEXEXTRACT(D25,""[\d]+""),""GB"")"),"1GB") -> 1GB | F25: =D25&E25 -> Conta de Email (1Gb) 500 Cx NOVO1GB | G25: 1 | H25: 500 | I25: GB | J25: 2842.06 | K25: Mensal | M25: =(if(L25="sob consulta","sob consulta", ROUND(L25*(1+pconfig!$B$6),2))) -> 0 | O25: =J25/H25 -> 5.68412 | P25: =ROUND(O25*(1+pconfig!$B$6),2) -> 5.87
A26: 2 - Data Center | B26: Hospedagem | C26: 5530 | D26: Conta de Email (1Gb) 1000 Cx NOVO | E26: =IFERROR(__xludf.DUMMYFUNCTION("CONCATENATE(REGEXEXTRACT(D26,""[\d]+""),""GB"")"),"1GB") -> 1GB | F26: =D26&E26 -> Conta de Email (1Gb) 1000 Cx NOVO1GB | G26: 1 | H26: 1000 | I26: GB | J26: 5615.92 | K26: Mensal | M26: =(if(L26="sob consulta","sob consulta", ROUND(L26*(1+pconfig!$B$6),2))) -> 0 | O26: =J26/H26 -> 5.61592 | P26: =ROUND(O26*(1+pconfig!$B$6),2) -> 5.8
A27: 2 - Data Center | B27: Hospedagem | C27: 5530 | D27: Conta de Email (2Gb) 1 Cx | E27: =IFERROR(__xludf.DUMMYFUNCTION("CONCATENATE(REGEXEXTRACT(D27,""[\d]+""),""GB"")"),"2GB") -> 2GB | F27: =D27&E27 -> Conta de Email (2Gb) 1 Cx2GB | G27: 1 | H27: 1 | I27: GB | J27: 7.18 | K27: Mensal | M27: =(if(L27="sob consulta","sob consulta", ROUND(L27*(1+pconfig!$B$6),2))) -> 0 | O27: =J27/H27 -> 7.18 | P27: =ROUND(O27*(1+pconfig!$B$6),2) -> 7.42
A28: 2 - Data Center | B28: Hospedagem | C28: 5530 | D28: Conta de Email (2Gb) 25 Cx | E28: =IFERROR(__xludf.DUMMYFUNCTION("CONCATENATE(REGEXEXTRACT(D28,""[\d]+""),""GB"")"),"2GB") -> 2GB | F28: =D28&E28 -> Conta de Email (2Gb) 25 Cx2GB | G28: 1 | H28: 25 | I28: GB | J28: 172.26 | K28: Mensal | M28: =(if(L28="sob consulta","sob consulta", ROUND(L28*(1+pconfig!$B$6),2))) -> 0 | O28: =J28/H28 -> 6.8904 | P28: =ROUND(O28*(1+pconfig!$B$6),2) -> 7.12
A29: 2 - Data Center | B29: Hospedagem | C29: 5530 | D29: Conta de Email (2Gb) 50 Cx | E29: =IFERROR(__xludf.DUMMYFUNCTION("CONCATENATE(REGEXEXTRACT(D29,""[\d]+""),""GB"")"),"2GB") -> 2GB | F29: =D29&E29 -> Conta de Email (2Gb) 50 Cx2GB | G29: 1 | H29: 50 | I29: GB | J29: 337.34 | K29: Mensal | M29: =(if(L29="sob consulta","sob consulta", ROUND(L29*(1+pconfig!$B$6),2))) -> 0 | O29: =J29/H29 -> 6.7468 | P29: =ROUND(O29*(1+pconfig!$B$6),2) -> 6.97
A30: 2 - Data Center | B30: Hospedagem | C30: 5530 | D30: Conta de Email (2Gb) 100 Cx | E30: =IFERROR(__xludf.DUMMYFUNCTION("CONCATENATE(REGEXEXTRACT(D30,""[\d]+""),""GB"")"),"2GB") -> 2GB | F30: =D30&E30 -> Conta de Email (2Gb) 100 Cx2GB | G30: 1 | H30: 100 | I30: GB | J30: 660.32 | K30: Mensal | M30: =(if(L30="sob consulta","sob consulta", ROUND(L30*(1+pconfig!$B$6),2))) -> 0 | O30: =J30/H30 -> 6.6032 | P30: =ROUND(O30*(1+pconfig!$B$6),2) -> 6.82
A31: 2 - Data Center | B31: Hospedagem | C31: 5530 | D31: Conta de Email (2Gb) 500 Cx NOVO | E31: =IFERROR(__xludf.DUMMYFUNCTION("CONCATENATE(REGEXEXTRACT(D31,""[\d]+""),""GB"")"),"2GB") -> 2GB | F31: =D31&E31 -> Conta de Email (2Gb) 500 Cx NOVO2GB | G31: 1 | H31: 500 | I31: GB | J31: 3006.9 | K31: Mensal | M31: =(if(L31="sob consulta","sob consulta", ROUND(L31*(1+pconfig!$B$6),2))) -> 0 | O31: =J31/H31 -> 6.0138 | P31: =ROUND(O31*(1+pconfig!$B$6),2) -> 6.21
A32: 2 - Data Center | B32: Hospedagem | C32: 5530 | D32: Conta de Email (2Gb) 1000 Cx NOVO | E32: =IFERROR(__xludf.DUMMYFUNCTION("CONCATENATE(REGEXEXTRACT(D32,""[\d]+""),""GB"")"),"2GB") -> 2GB | F32: =D32&E32 -> Conta de Email (2Gb) 1000 Cx NOVO2GB | G32: 1 | H32: 1000 | I32: GB | J32: 5888.76 | K32: Mensal | M32: =(if(L32="sob consulta","sob consulta", ROUND(L32*(1+pconfig!$B$6),2))) -> 0 | O32: =J32/H32 -> 5.88876 | P32: =ROUND(O32*(1+pconfig!$B$6),2) -> 6.08
A33: 2 - Data Center | B33: Hospedagem | C33: 5530 | D33: Conta de Email (5Gb) 1 Cx | E33: =IFERROR(__xludf.DUMMYFUNCTION("CONCATENATE(REGEXEXTRACT(D33,""[\d]+""),""GB"")"),"5GB") -> 5GB | F33: =D33&E33 -> Conta de Email (5Gb) 1 Cx5GB | G33: 1 | H33: 1 | I33: GB | J33: 8.61 | K33: Mensal | M33: =(if(L33="sob consulta","sob consulta", ROUND(L33*(1+pconfig!$B$6),2))) -> 0 | N33: 8.61 | O33: =J33/H33 -> 8.61 | P33: =ROUND(O33*(1+pconfig!$B$6),2) -> 8.89
A34: 2 - Data Center | B34: Hospedagem | C34: 5530 | D34: Conta de Email (5Gb) 25 Cx | E34: =IFERROR(__xludf.DUMMYFUNCTION("CONCATENATE(REGEXEXTRACT(D34,""[\d]+""),""GB"")"),"5GB") -> 5GB | F34: =D34&E34 -> Conta de Email (5Gb) 25 Cx5GB | G34: 1 | H34: 25 | I34: GB | J34: 206.64 | K34: Mensal | M34: =(if(L34="sob consulta","sob consulta", ROUND(L34*(1+pconfig!$B$6),2))) -> 0 | O34: =J34/H34 -> 8.2656 | P34: =ROUND(O34*(1+pconfig!$B$6),2) -> 8.54
A35: 2 - Data Center | B35: Hospedagem | C35: 5530 | D35: Conta de Email (5Gb) 50 Cx | E35: =IFERROR(__xludf.DUMMYFUNCTION("CONCATENATE(REGEXEXTRACT(D35,""[\d]+""),""GB"")"),"5GB") -> 5GB | F35: =D35&E35 -> Conta de Email (5Gb) 50 Cx5GB | G35: 1 | H35: 50 | I35: GB | J35: 404.68 | K35: Mensal | M35: =(if(L35="sob consulta","sob consulta", ROUND(L35*(1+pconfig!$B$6),2))) -> 0 | O35: =J35/H35 -> 8.0936 | P35: =ROUND(O35*(1+pconfig!$B$6),2) -> 8.36
A36: 2 - Data Center | B36: Hospedagem | C36: 5530 | D36: Conta de Email (5Gb) 100 Cx | E36: =IFERROR(__xludf.DUMMYFUNCTION("CONCATENATE(REGEXEXTRACT(D36,""[\d]+""),""GB"")"),"5GB") -> 5GB | F36: =D36&E36 -> Conta de Email (5Gb) 100 Cx5GB | G36: 1 | H36: 100 | I36: GB | J36: 792.14 | K36: Mensal | M36: =(if(L36="sob consulta","sob consulta", ROUND(L36*(1+pconfig!$B$6),2))) -> 0 | O36: =J36/H36 -> 7.9214 | P36: =ROUND(O36*(1+pconfig!$B$6),2) -> 8.18
A37: 2 - Data Center | B37: Hospedagem | C37: 5530 | D37: Conta de Email (5Gb) 500 Cx NOVO | E37: =IFERROR(__xludf.DUMMYFUNCTION("CONCATENATE(REGEXEXTRACT(D37,""[\d]+""),""GB"")"),"5GB") -> 5GB | F37: =D37&E37 -> Conta de Email (5Gb) 500 Cx NOVO5GB | G37: 1 | H37: 500 | I37: GB | J37: 3387.74 | K37: Mensal | M37: =(if(L37="sob consulta","sob consulta", ROUND(L37*(1+pconfig!$B$6),2))) -> 0 | O37: =J37/H37 -> 6.77548 | P37: =ROUND(O37*(1+pconfig!$B$6),2) -> 7
A38: 2 - Data Center | B38: Hospedagem | C38: 5530 | D38: Conta de Email (5Gb) 1000 Cx NOVO | E38: =IFERROR(__xludf.DUMMYFUNCTION("CONCATENATE(REGEXEXTRACT(D38,""[\d]+""),""GB"")"),"5GB") -> 5GB | F38: =D38&E38 -> Conta de Email (5Gb) 1000 Cx NOVO5GB | G38: 1 | H38: 1000 | I38: GB | J38: 6502.64 | K38: Mensal | M38: =(if(L38="sob consulta","sob consulta", ROUND(L38*(1+pconfig!$B$6),2))) -> 0 | O38: =J38/H38 -> 6.50264 | P38: =ROUND(O38*(1+pconfig!$B$6),2) -> 6.72
A39: 2 - Data Center | B39: Hospedagem | C39: 5530 | D39: Conta de Email (10Gb) 1 Cx | E39: =IFERROR(__xludf.DUMMYFUNCTION("CONCATENATE(REGEXEXTRACT(D39,""[\d]+""),""GB"")"),"10GB") -> 10GB | F39: =D39&E39 -> Conta de Email (10Gb) 1 Cx10GB | G39: 1 | H39: 1 | I39: GB | J39: 11.19 | K39: Mensal | M39: =(if(L39="sob consulta","sob consulta", ROUND(L39*(1+pconfig!$B$6),2))) -> 0 | O39: =J39/H39 -> 11.19 | P39: =ROUND(O39*(1+pconfig!$B$6),2) -> 11.56
A40: 2 - Data Center | B40: Hospedagem | C40: 5530 | D40: Conta de Email (10Gb) 25 Cx | E40: =IFERROR(__xludf.DUMMYFUNCTION("CONCATENATE(REGEXEXTRACT(D40,""[\d]+""),""GB"")"),"10GB") -> 10GB | F40: =D40&E40 -> Conta de Email (10Gb) 25 Cx10GB | G40: 1 | H40: 25 | I40: GB | J40: 268.67 | K40: Mensal | M40: =(if(L40="sob consulta","sob consulta", ROUND(L40*(1+pconfig!$B$6),2))) -> 0 | O40: =J40/H40 -> 10.7468 | P40: =ROUND(O40*(1+pconfig!$B$6),2) -> 11.1
...

Sheet linkdados
A1: item | B1: MunicIpio | C1: Modalidade | D1: tecnologias | E1: indice | F1: Mbps | G1: Mesorreg | H1: ATENDIDO | I1: Regint | J1: Degrau | K1: UnitTransporte | L1: UnitTransFinal | M1: Cmanut | N1: Cmanutfinal | O1: Preço Final | P1: PvTranporte | Q1: PvTransportDesc | R1: PvFinal
A2: 1 | B2: ABAETETUBA | C2: RADIO | D2: ALVARION, CALIUM, AIRMUX | E2: =B2&C2 -> ABAETETUBARADIO | F2: 1 | G2: NORDESTE | H2: {=XLOOKUP(B2,municipios,regiao!$D$6:$D$150,0)} -> SIM | I2: TOCANTINS | J2: D2 | K2: 15.65 | L2: =K2/(1-pconfig!$G$2-pconfig!$G$3-pconfig!$G$4) -> 29.550604 | M2: 138.285 | N2: =M2/(1-pconfig!$G$2-pconfig!$G$3-pconfig!$G$4) -> 261.11216 | O2: =((K2*F2)+M2)/(1-pconfig!$G$2-pconfig!$G$3-pconfig!$G$4) -> 290.66276 | P2: =K2*F2/(1-pconfig!$G$2-pconfig!$G$3-pconfig!$G$4) -> 29.550604 | Q2: =IFS(F2<=pconfig!$B$12,P2*pconfig!$C$12,F2<=pconfig!$B$13,P2*pconfig!$C$13,F2<=pconfig!$B$14,P2*pconfig!$C$14,F2<=pconfig!$B$15,P2*pconfig!$C$15,F2<=pconfig!$B$16,P2*pconfig!$C$16,F2<=pconfig!$B$17,P2*pconfig!$C$17,F2<=pconfig!$B$18,P2*pconfig!$C$18,F2<=pconfig!$B$19,P2*pconfig!$C$19,F2<=pconfig!$B$20,P2*pconfig!$C$20,F2<=pconfig!$B$21,P2*pconfig!$C$21) -> 29.550604 | R2: =IF(Q2=0,P2+N2,Q2+N2) -> 290.66276
A3: =A2+1 -> 2 | B3: ABAETETUBA | C3: FIBRA | D3: METRO, GPON | E3: =B3&C3 -> ABAETETUBAFIBRA | F3: 1 | G3: NORDESTE | H3: {=XLOOKUP(B3,municipios,regiao!$D$6:$D$150,0)} -> SIM | I3: TOCANTINS | J3: D2 | K3: 15.65 | L3: =K3/(1-pconfig!$G$2-pconfig!$G$3-pconfig!$G$4) -> 29.550604 | M3: 314.77 | N3: =M3/(1-pconfig!$G$2-pconfig!$G$3-pconfig!$G$4) -> 594.35423 | O3: =((K3*F3)+M3)/(1-pconfig!$G$2-pconfig!$G$3-pconfig!$G$4) -> 623.90483 | P3: =(K3*F3/(1-pconfig!$G$2-pconfig!$G$3-pconfig!$G$4)) -> 29.550604 | Q3: =IFS(F3<=pconfig!$B$12,P3*pconfig!$C$12,F3<=pconfig!$B$13,P3*pconfig!$C$13,F3<=pconfig!$B$14,P3*pconfig!$C$14,F3<=pconfig!$B$15,P3*pconfig!$C$15,F3<=pconfig!$B$16,P3*pconfig!$C$16,F3<=pconfig!$B$17,P3*pconfig!$C$17,F3<=pconfig!$B$18,P3*pconfig!$C$18,F3<=pconfig!$B$19,P3*pconfig!$C$19,F3<=pconfig!$B$20,P3*pconfig!$C$20,F3<=pconfig!$B$21,P3*pconfig!$C$21) -> 29.550604 | R3: =IF(Q3=0,P3+N3,Q3+N3) -> 623.90483
A4: =A3+1 -> 3 | B4: ABAETETUBA | C4: SATELITE | D4: TELEBRAS | E4: =B4&C4 -> ABAETETUBASATELITE | F4: 1 | G4: NORDESTE | H4: {=XLOOKUP(B4,municipios,regiao!$D$6:$D$150,0)} -> SIM | I4: TOCANTINS | J4: - | K4: 4799 | L4: =K4/(1-pconfig!$G$2-pconfig!$G$3-pconfig!$G$4) -> 9061.5559 | M4: 314.77 | N4: =M4/(1-pconfig!$G$2-pconfig!$G$3-pconfig!$G$4) -> 594.35423 | O4: =((K4*F4)+M4)/(1-pconfig!$G$2-pconfig!$G$3-pconfig!$G$4) -> 9655.9101 | P4: =K4*F4/(1-pconfig!$G$2-pconfig!$G$3-pconfig!$G$4) -> 9061.5559 | Q4: =IFS(F4<=pconfig!$B$12,P4*pconfig!$C$12,F4<=pconfig!$B$13,P4*pconfig!$C$13,F4<=pconfig!$B$14,P4*pconfig!$C$14,F4<=pconfig!$B$15,P4*pconfig!$C$15,F4<=pconfig!$B$16,P4*pconfig!$C$16,F4<=pconfig!$B$17,P4*pconfig!$C$17,F4<=pconfig!$B$18,P4*pconfig!$C$18,F4<=pconfig!$B$19,P4*pconfig!$C$19,F4<=pconfig!$B$20,P4*pconfig!$C$20,F4<=pconfig!$B$21,P4*pconfig!$C$21) -> 9061.5559 | R4: =IF(Q4=0,P4+N4,Q4+N4) -> 9655.9101
A5: =A4+1 -> 4 | B5: ABEL FIGUEIREDO | C5: FIBRA | D5: METRO, GPON | E5: =B5&C5 -> ABEL FIGUEIREDOFIBRA | F5: 1 | G5: SUDESTE | H5: {=XLOOKUP(B5,municipios,regiao!$D$6:$D$150,0)} -> NÃO | I5: RIO CAPIM | J5: D6 | K5: 29.29 | L5: =K5/(1-pconfig!$G$2-pconfig!$G$3-pconfig!$G$4) -> 55.305891 | M5: 63.39 | N5: =M5/(1-pconfig!$G$2-pconfig!$G$3-pconfig!$G$4) -> 119.69411 | O5: =((K5*F5)+M5)/(1-pconfig!$G$2-pconfig!$G$3-pconfig!$G$4) -> 175 | P5: =K5*F5/(1-pconfig!$G$2-pconfig!$G$3-pconfig!$G$4) -> 55.305891 | Q5: =IFS(F5<=pconfig!$B$12,P5*pconfig!$C$12,F5<=pconfig!$B$13,P5*pconfig!$C$13,F5<=pconfig!$B$14,P5*pconfig!$C$14,F5<=pconfig!$B$15,P5*pconfig!$C$15,F5<=pconfig!$B$16,P5*pconfig!$C$16,F5<=pconfig!$B$17,P5*pconfig!$C$17,F5<=pconfig!$B$18,P5*pconfig!$C$18,F5<=pconfig!$B$19,P5*pconfig!$C$19,F5<=pconfig!$B$20,P5*pconfig!$C$20,F5<=pconfig!$B$21,P5*pconfig!$C$21) -> 55.305891 | R5: =IF(Q5=0,P5+N5,Q5+N5) -> 175
A6: =A5+1 -> 5 | B6: ABEL FIGUEIREDO | C6: SATELITE | D6: TELEBRAS | E6: =B6&C6 -> ABEL FIGUEIREDOSATELITE | F6: 1 | G6: SUDESTE | H6: {=XLOOKUP(B6,municipios,regiao!$D$6:$D$150,0)} -> NÃO | I6: RIO CAPIM | J6: - | K6: 4799 | L6: =K6/(1-pconfig!$G$2-pconfig!$G$3-pconfig!$G$4) -> 9061.5559 | M6: 63.39 | N6: =M6/(1-pconfig!$G$2-pconfig!$G$3-pconfig!$G$4) -> 119.69411 | O6: =((K6*F6)+M6)/(1-pconfig!$G$2-pconfig!$G$3-pconfig!$G$4) -> 9181.25 | P6: =K6*F6/(1-pconfig!$G$2-pconfig!$G$3-pconfig!$G$4) -> 9061.5559 | Q6: =IFS(F6<=pconfig!$B$12,P6*pconfig!$C$12,F6<=pconfig!$B$13,P6*pconfig!$C$13,F6<=pconfig!$B$14,P6*pconfig!$C$14,F6<=pconfig!$B$15,P6*pconfig!$C$15,F6<=pconfig!$B$16,P6*pconfig!$C$16,F6<=pconfig!$B$17,P6*pconfig!$C$17,F6<=pconfig!$B$18,P6*pconfig!$C$18,F6<=pconfig!$B$19,P6*pconfig!$C$19,F6<=pconfig!$B$20,P6*pconfig!$C$20,F6<=pconfig!$B$21,P6*pconfig!$C$21) -> 9061.5559 | R6: =IF(Q6=0,P6+N6,Q6+N6) -> 9181.25
A7: =A6+1 -> 6 | B7: ABEL FIGUEIREDO | C7: RADIO | D7: ALVARION, CALIUM, AIRMUX | E7: =B7&C7 -> ABEL FIGUEIREDORADIO | F7: 1 | G7: SUDESTE | H7: {=XLOOKUP(B7,municipios,regiao!$D$6:$D$150,0)} -> NÃO | I7: RIO CAPIM | J7: D6 | K7: 29.29 | L7: =K7/(1-pconfig!$G$2-pconfig!$G$3-pconfig!$G$4) -> 55.305891 | M7: 333.33333 | N7: =M7/(1-pconfig!$G$2-pconfig!$G$3-pconfig!$G$4) -> 629.40584 | O7: =((K7*F7)+M7)/(1-pconfig!$G$2-pconfig!$G$3-pconfig!$G$4) -> 684.71173 | P7: =K7*F7/(1-pconfig!$G$2-pconfig!$G$3-pconfig!$G$4) -> 55.305891 | Q7: =IFS(F7<=pconfig!$B$12,P7*pconfig!$C$12,F7<=pconfig!$B$13,P7*pconfig!$C$13,F7<=pconfig!$B$14,P7*pconfig!$C$14,F7<=pconfig!$B$15,P7*pconfig!$C$15,F7<=pconfig!$B$16,P7*pconfig!$C$16,F7<=pconfig!$B$17,P7*pconfig!$C$17,F7<=pconfig!$B$18,P7*pconfig!$C$18,F7<=pconfig!$B$19,P7*pconfig!$C$19,F7<=pconfig!$B$20,P7*pconfig!$C$20,F7<=pconfig!$B$21,P7*pconfig!$C$21) -> 55.305891 | R7: =IF(Q7=0,P7+N7,Q7+N7) -> 684.71173
A8: =A7+1 -> 7 | B8: ACARA | C8: RADIO | D8: ALVARION, CALIUM, AIRMUX | E8: =B8&C8 -> ACARARADIO | F8: 1 | G8: NORDESTE | H8: {=XLOOKUP(B8,municipios,regiao!$D$6:$D$150,0)} -> NÃO | I8: TOCANTINS | J8: D4 | K8: 20.69 | L8: =K8/(1-pconfig!$G$2-pconfig!$G$3-pconfig!$G$4) -> 39.067221 | M8: 138.285 | N8: =M8/(1-pconfig!$G$2-pconfig!$G$3-pconfig!$G$4) -> 261.11216 | O8: =((K8*F8)+M8)/(1-pconfig!$G$2-pconfig!$G$3-pconfig!$G$4) -> 300.17938 | P8: =K8*F8/(1-pconfig!$G$2-pconfig!$G$3-pconfig!$G$4) -> 39.067221 | Q8: =IFS(F8<=pconfig!$B$12,P8*pconfig!$C$12,F8<=pconfig!$B$13,P8*pconfig!$C$13,F8<=pconfig!$B$14,P8*pconfig!$C$14,F8<=pconfig!$B$15,P8*pconfig!$C$15,F8<=pconfig!$B$16,P8*pconfig!$C$16,F8<=pconfig!$B$17,P8*pconfig!$C$17,F8<=pconfig!$B$18,P8*pconfig!$C$18,F8<=pconfig!$B$19,P8*pconfig!$C$19,F8<=pconfig!$B$20,P8*pconfig!$C$20,F8<=pconfig!$B$21,P8*pconfig!$C$21) -> 39.067221 | R8: =IF(Q8=0,P8+N8,Q8+N8) -> 300.17938
A9: =A8+1 -> 8 | B9: ACARA | C9: FIBRA | D9: METRO, GPON | E9: =B9&C9 -> ACARAFIBRA | F9: 1 | G9: NORDESTE | H9: {=XLOOKUP(B9,municipios,regiao!$D$6:$D$150,0)} -> NÃO | I9: TOCANTINS | J9: D4 | K9: 20.69 | L9: =K9/(1-pconfig!$G$2-pconfig!$G$3-pconfig!$G$4) -> 39.067221 | M9: 314.77 | N9: =M9/(1-pconfig!$G$2-pconfig!$G$3-pconfig!$G$4) -> 594.35423 | O9: =((K9*F9)+M9)/(1-pconfig!$G$2-pconfig!$G$3-pconfig!$G$4) -> 633.42145 | P9: =K9*F9/(1-pconfig!$G$2-pconfig!$G$3-pconfig!$G$4) -> 39.067221 | Q9: =IFS(F9<=pconfig!$B$12,P9*pconfig!$C$12,F9<=pconfig!$B$13,P9*pconfig!$C$13,F9<=pconfig!$B$14,P9*pconfig!$C$14,F9<=pconfig!$B$15,P9*pconfig!$C$15,F9<=pconfig!$B$16,P9*pconfig!$C$16,F9<=pconfig!$B$17,P9*pconfig!$C$17,F9<=pconfig!$B$18,P9*pconfig!$C$18,F9<=pconfig!$B$19,P9*pconfig!$C$19,F9<=pconfig!$B$20,P9*pconfig!$C$20,F9<=pconfig!$B$21,P9*pconfig!$C$21) -> 39.067221 | R9: =IF(Q9=0,P9+N9,Q9+N9) -> 633.42145
A10: =A9+1 -> 9 | B10: ACARA | C10: SATELITE | D10: TELEBRAS | E10: =B10&C10 -> ACARASATELITE | F10: 1 | G10: NORDESTE | H10: {=XLOOKUP(B10,municipios,regiao!$D$6:$D$150,0)} -> NÃO | I10: TOCANTINS | J10: - | K10: 4799 | L10: =K10/(1-pconfig!$G$2-pconfig!$G$3-pconfig!$G$4) -> 9061.5559 | M10: 314.77 | N10: =M10/(1-pconfig!$G$2-pconfig!$G$3-pconfig!$G$4) -> 594.35423 | O10: =((K10*F10)+M10)/(1-pconfig!$G$2-pconfig!$G$3-pconfig!$G$4) -> 9655.9101 | P10: =K10*F10/(1-pconfig!$G$2-pconfig!$G$3-pconfig!$G$4) -> 9061.5559 | Q10: =IFS(F10<=pconfig!$B$12,P10*pconfig!$C$12,F10<=pconfig!$B$13,P10*pconfig!$C$13,F10<=pconfig!$B$14,P10*pconfig!$C$14,F10<=pconfig!$B$15,P10*pconfig!$C$15,F10<=pconfig!$B$16,P10*pconfig!$C$16,F10<=pconfig!$B$17,P10*pconfig!$C$17,F10<=pconfig!$B$18,P10*pconfig!$C$18,F10<=pconfig!$B$19,P10*pconfig!$C$19,F10<=pconfig!$B$20,P10*pconfig!$C$20,F10<=pconfig!$B$21,P10*pconfig!$C$21) -> 9061.5559 | R10: =IF(Q10=0,P10+N10,Q10+N10) -> 9655.9101
A11: =A10+1 -> 10 | B11: AFUA | C11: RADIO | D11: ALVARION, CALIUM, AIRMUX | E11: =B11&C11 -> AFUARADIO | F11: 1 | G11: MARAJÓ | H11: {=XLOOKUP(B11,municipios,regiao!$D$6:$D$150,0)} -> NÃO | I11: MARAJÓ | J11: D7 | K11: 35.73 | L11: =K11/(1-pconfig!$G$2-pconfig!$G$3-pconfig!$G$4) -> 67.466012 | M11: 106.69333 | N11: =M11/(1-pconfig!$G$2-pconfig!$G$3-pconfig!$G$4) -> 201.46022 | O11: =((K11*F11)+M11)/(1-pconfig!$G$2-pconfig!$G$3-pconfig!$G$4) -> 268.92623 | P11: =K11*F11/(1-pconfig!$G$2-pconfig!$G$3-pconfig!$G$4) -> 67.466012 | Q11: =IFS(F11<=pconfig!$B$12,P11*pconfig!$C$12,F11<=pconfig!$B$13,P11*pconfig!$C$13,F11<=pconfig!$B$14,P11*pconfig!$C$14,F11<=pconfig!$B$15,P11*pconfig!$C$15,F11<=pconfig!$B$16,P11*pconfig!$C$16,F11<=pconfig!$B$17,P11*pconfig!$C$17,F11<=pconfig!$B$18,P11*pconfig!$C$18,F11<=pconfig!$B$19,P11*pconfig!$C$19,F11<=pconfig!$B$20,P11*pconfig!$C$20,F11<=pconfig!$B$21,P11*pconfig!$C$21) -> 67.466012 | R11: =IF(Q11=0,P11+N11,Q11+N11) -> 268.92623
A12: =A11+1 -> 11 | B12: AFUA | C12: FIBRA | D12: METRO, GPON | E12: =B12&C12 -> AFUAFIBRA | F12: 1 | G12: MARAJÓ | H12: {=XLOOKUP(B12,municipios,regiao!$D$6:$D$150,0)} -> NÃO | I12: MARAJÓ | J12: D7 | K12: 35.73 | L12: =K12/(1-pconfig!$G$2-pconfig!$G$3-pconfig!$G$4) -> 67.466012 | M12: 519.17 | N12: =M12/(1-pconfig!$G$2-pconfig!$G$3-pconfig!$G$4) -> 980.30589 | O12: =((K12*F12)+M12)/(1-pconfig!$G$2-pconfig!$G$3-pconfig!$G$4) -> 1047.7719 | P12: =K12*F12/(1-pconfig!$G$2-pconfig!$G$3-pconfig!$G$4) -> 67.466012 | Q12: =IFS(F12<=pconfig!$B$12,P12*pconfig!$C$12,F12<=pconfig!$B$13,P12*pconfig!$C$13,F12<=pconfig!$B$14,P12*pconfig!$C$14,F12<=pconfig!$B$15,P12*pconfig!$C$15,F12<=pconfig!$B$16,P12*pconfig!$C$16,F12<=pconfig!$B$17,P12*pconfig!$C$17,F12<=pconfig!$B$18,P12*pconfig!$C$18,F12<=pconfig!$B$19,P12*pconfig!$C$19,F12<=pconfig!$B$20,P12*pconfig!$C$20,F12<=pconfig!$B$21,P12*pconfig!$C$21) -> 67.466012 | R12: =IF(Q12=0,P12+N12,Q12+N12) -> 1047.7719
A13: =A12+1 -> 12 | B13: AFUA | C13: SATELITE | D13: TELEBRAS | E13: =B13&C13 -> AFUASATELITE | F13: 1 | G13: MARAJÓ | H13: {=XLOOKUP(B13,municipios,regiao!$D$6:$D$150,0)} -> NÃO | I13: MARAJÓ | J13: - | K13: 4799 | L13: =K13/(1-pconfig!$G$2-pconfig!$G$3-pconfig!$G$4) -> 9061.5559 | M13: 519.17 | N13: =M13/(1-pconfig!$G$2-pconfig!$G$3-pconfig!$G$4) -> 980.30589 | O13: =((K13*F13)+M13)/(1-pconfig!$G$2-pconfig!$G$3-pconfig!$G$4) -> 10041.862 | P13: =K13*F13/(1-pconfig!$G$2-pconfig!$G$3-pconfig!$G$4) -> 9061.5559 | Q13: =IFS(F13<=pconfig!$B$12,P13*pconfig!$C$12,F13<=pconfig!$B$13,P13*pconfig!$C$13,F13<=pconfig!$B$14,P13*pconfig!$C$14,F13<=pconfig!$B$15,P13*pconfig!$C$15,F13<=pconfig!$B$16,P13*pconfig!$C$16,F13<=pconfig!$B$17,P13*pconfig!$C$17,F13<=pconfig!$B$18,P13*pconfig!$C$18,F13<=pconfig!$B$19,P13*pconfig!$C$19,F13<=pconfig!$B$20,P13*pconfig!$C$20,F13<=pconfig!$B$21,P13*pconfig!$C$21) -> 9061.5559 | R13: =IF(Q13=0,P13+N13,Q13+N13) -> 10041.862
A14: =A13+1 -> 13 | B14: AGUA AZUL DO NORTE | C14: RADIO | D14: ALVARION, CALIUM, AIRMUX | E14: =B14&C14 -> AGUA AZUL DO NORTERADIO | F14: 1 | G14: SUDESTE | H14: {=XLOOKUP(B14,municipios,regiao!$D$6:$D$150,0)} -> NÃO | I14: ARAGUAIA | J14: D6 | K14: 29.29 | L14: =K14/(1-pconfig!$G$2-pconfig!$G$3-pconfig!$G$4) -> 55.305891 | M14: 336.07417 | N14: =M14/(1-pconfig!$G$2-pconfig!$G$3-pconfig!$G$4) -> 634.58113 | O14: =((K14*F14)+M14)/(1-pconfig!$G$2-pconfig!$G$3-pconfig!$G$4) -> 689.88702 | P14: =K14*F14/(1-pconfig!$G$2-pconfig!$G$3-pconfig!$G$4) -> 55.305891 | Q14: =IFS(F14<=pconfig!$B$12,P14*pconfig!$C$12,F14<=pconfig!$B$13,P14*pconfig!$C$13,F14<=pconfig!$B$14,P14*pconfig!$C$14,F14<=pconfig!$B$15,P14*pconfig!$C$15,F14<=pconfig!$B$16,P14*pconfig!$C$16,F14<=pconfig!$B$17,P14*pconfig!$C$17,F14<=pconfig!$B$18,P14*pconfig!$C$18,F14<=pconfig!$B$19,P14*pconfig!$C$19,F14<=pconfig!$B$20,P14*pconfig!$C$20,F14<=pconfig!$B$21,P14*pconfig!$C$21) -> 55.305891 | R14: =IF(Q14=0,P14+N14,Q14+N14) -> 689.88702
A15: =A14+1 -> 14 | B15: AGUA AZUL DO NORTE | C15: FIBRA | D15: METRO, GPON | E15: =B15&C15 -> AGUA AZUL DO NORTEFIBRA | F15: 1 | G15: SUDESTE | H15: {=XLOOKUP(B15,municipios,regiao!$D$6:$D$150,0)} -> NÃO | I15: ARAGUAIA | J15: D6 | K15: 29.29 | L15: =K15/(1-pconfig!$G$2-pconfig!$G$3-pconfig!$G$4) -> 55.305891 | M15: 447.5 | N15: =M15/(1-pconfig!$G$2-pconfig!$G$3-pconfig!$G$4) -> 844.97734 | O15: =((K15*F15)+M15)/(1-pconfig!$G$2-pconfig!$G$3-pconfig!$G$4) -> 900.28323 | P15: =K15*F15/(1-pconfig!$G$2-pconfig!$G$3-pconfig!$G$4) -> 55.305891 | Q15: =IFS(F15<=pconfig!$B$12,P15*pconfig!$C$12,F15<=pconfig!$B$13,P15*pconfig!$C$13,F15<=pconfig!$B$14,P15*pconfig!$C$14,F15<=pconfig!$B$15,P15*pconfig!$C$15,F15<=pconfig!$B$16,P15*pconfig!$C$16,F15<=pconfig!$B$17,P15*pconfig!$C$17,F15<=pconfig!$B$18,P15*pconfig!$C$18,F15<=pconfig!$B$19,P15*pconfig!$C$19,F15<=pconfig!$B$20,P15*pconfig!$C$20,F15<=pconfig!$B$21,P15*pconfig!$C$21) -> 55.305891 | R15: =IF(Q15=0,P15+N15,Q15+N15) -> 900.28323
... A433: =A432+1 -> 432 | B433: XINGUARA | C433: SATELITE | D433: TELEBRAS | E433: =B433&C433 -> XINGUARASATELITE | F433: 1 | G433: SUDESTE | H433: {=XLOOKUP(B433,municipios,regiao!$D$6:$D$150,0)} -> SIM | I433: ARAGUAIA | J433: - | K433: 4799 | L433: =K433/(1-pconfig!$G$2-pconfig!$G$3-pconfig!$G$4) -> 9061.5559 | M433: 447.5 | N433: =M433/(1-pconfig!$G$2-pconfig!$G$3-pconfig!$G$4) -> 844.97734 | O433: =((K433*F433)+M433)/(1-pconfig!$G$2-pconfig!$G$3-pconfig!$G$4) -> 9906.5332 | P433: =K433*F433/(1-pconfig!$G$2-pconfig!$G$3-pconfig!$G$4) -> 9061.5559 | Q433: =IFS(F433<=pconfig!$B$12,P433*pconfig!$C$12,F433<=pconfig!$B$13,P433*pconfig!$C$13,F433<=pconfig!$B$14,P433*pconfig!$C$14,F433<=pconfig!$B$15,P433*pconfig!$C$15,F433<=pconfig!$B$16,P433*pconfig!$C$16,F433<=pconfig!$B$17,P433*pconfig!$C$17,F433<=pconfig!$B$18,P433*pconfig!$C$18,F433<=pconfig!$B$19,P433*pconfig!$C$19,F433<=pconfig!$B$20,P433*pconfig!$C$20,F433<=pconfig!$B$21,P433*pconfig!$C$21) -> 9061.5559 | R433: =IF(Q433=0,P433+N433,Q433+N433) -> 9906.5332

Sheet contatos
A1: =IFERROR(__xludf.DUMMYFUNCTION("IMPORTRANGE(""https://docs.google.com/spreadsheets/d/1fiSxYvppz5DsfdaqAWe6egd1vzr2a7h0sdUdR2hpq6w/edit?usp=sharing"",""Contatos!A:J"")"),"Id") -> Id | B1: =IFERROR(__xludf.DUMMYFUNCTION("""COMPUTED_VALUE"""),"CodUnico") -> CodUnico | C1: =IFERROR(__xludf.DUMMYFUNCTION("""COMPUTED_VALUE"""),"Sigla") -> Sigla | D1: =IFERROR(__xludf.DUMMYFUNCTION("""COMPUTED_VALUE"""),"Contato") -> Contato | E1: =IFERROR(__xludf.DUMMYFUNCTION("""COMPUTED_VALUE"""),"Cargo") -> Cargo | F1: =IFERROR(__xludf.DUMMYFUNCTION("""COMPUTED_VALUE"""),"Setor") -> Setor | G1: =IFERROR(__xludf.DUMMYFUNCTION("""COMPUTED_VALUE"""),"Telefone") -> Telefone | H1: =IFERROR(__xludf.DUMMYFUNCTION("""COMPUTED_VALUE"""),"Celular") -> Celular | I1: =IFERROR(__xludf.DUMMYFUNCTION("""COMPUTED_VALUE"""),"Email principal") -> Email principal | J1: =IFERROR(__xludf.DUMMYFUNCTION("""COMPUTED_VALUE"""),"Email secundario") -> Email secundario
B2: =IFERROR(__xludf.DUMMYFUNCTION("""COMPUTED_VALUE"""),"ADEPARÁ1") -> ADEPARÁ1 | C2: =IFERROR(__xludf.DUMMYFUNCTION("""COMPUTED_VALUE"""),"ADEPARÁ") -> ADEPARÁ | D2: =IFERROR(__xludf.DUMMYFUNCTION("""COMPUTED_VALUE"""),"Emerson Ribeiro da Silva") -> Emerson Ribeiro da Silva | F2: =IFERROR(__xludf.DUMMYFUNCTION("""COMPUTED_VALUE"""),"Gerência de Tecnologia da Informação - GTI") -> Gerência de Tecnologia da Informação - GTI | I2: =IFERROR(__xludf.DUMMYFUNCTION("""COMPUTED_VALUE"""),"gti@adepara.pa.gov.br") -> gti@adepara.pa.gov.br
B3: =IFERROR(__xludf.DUMMYFUNCTION("""COMPUTED_VALUE"""),"ADEPARÁ2") -> ADEPARÁ2 | C3: =IFERROR(__xludf.DUMMYFUNCTION("""COMPUTED_VALUE"""),"ADEPARÁ") -> ADEPARÁ | D3: =IFERROR(__xludf.DUMMYFUNCTION("""COMPUTED_VALUE"""),"Hugo ") -> Hugo | E3: =IFERROR(__xludf.DUMMYFUNCTION("""COMPUTED_VALUE"""),"Técnico/Analista") -> Técnico/Analista | F3: =IFERROR(__xludf.DUMMYFUNCTION("""COMPUTED_VALUE"""),"Gerência de Tecnologia da Informação - GTI") -> Gerência de Tecnologia da Informação - GTI | H3: =IFERROR(__xludf.DUMMYFUNCTION("""COMPUTED_VALUE"""),"(91) 9122-0441") -> (91) 9122-0441 | I3: =IFERROR(__xludf.DUMMYFUNCTION("""COMPUTED_VALUE"""),"inteligencia@adepara.pa.gov.br") -> inteligencia@adepara.pa.gov.br
